Workbook

Sheet LEGGIMI
A1: COME SI USA QUESTO FILE
A3: 1. Ogni foglio è una tabella del database dell'app. Modifica solo le celle: non cambiare i nomi dei fogli né le intestazioni della prima riga.
A4: 2. Le colonne che iniziano con _ (verdi) sono solo di aiuto: mostrano il nome dell'area, dell'autostrada o del gestore. Non vengono lette.
A5: 3. Per aggiungere una colonnina: nel foglio aree_colonnine scrivi una nuova riga in fondo (id nuovo = ultimo id + 1; id_area = numero dell'area, lo trovi nel foglio aree_servizio; id_gestore dal foglio gestori_ricarica).
A6: 4. Per nascondere un'area dall'app: nel foglio aree_servizio metti attiva_2026 = 0. Per mostrarla: 1. (-1 = esclusa, non è su autostrada).
A7: 4b. Listino ricarica (foglio tariffe_ricarica): una riga per gestore, corrente (AC/DC) e fascia di potenza (potenza_min_kw–potenza_max_kw). Prezzi a consumo senza abbonamento, IVA inclusa. stato = 'verificato' oppure 'da verificare'. data_fonte = data del listino. Il prezzo scritto in una riga di aree_colonnine (es. A22) vince sul listino.
A8: 5. Per segnare un'area chiusa: colonna stato = 'chiusa (temporaneamente)'; per riaprirla: 'aperta'.
A9: 6. Date nel formato AAAA-MM-GG (per esempio 2026-10-14). Prezzi e potenze con il punto o la virgola come li scrive il tuo Excel.
A10: 7. Celle vuote sono valide (valore mancante). Righe completamente vuote vengono ignorate.
A11: 8. Salva con lo stesso nome (dati.xlsx) e caricalo dalla pagina di aggiornamento. Se c'è un errore, la pagina te lo spiega in italiano e l'app continua a usare i dati vecchi.
A13: COSA NON FARE: non cambiare gli id di righe esistenti, non cancellare un'area se ha righe collegate (colonnine, marche, servizi, prezzi): togli prima quelle righe, o metti attiva_2026 = 0.

Sheet aree_colonnine
A1: id | B1: id_area | C1: id_gestore | D1: numero_colonnine | E1: tipo_corrente | F1: potenza_kw | G1: prezzo_kwh | H1: fonte | I1: data_aggiornamento | J1: _area | K1: _gestore
A2: 1 | B2: 2 | C2: 1 | D2: 1 | E2: AC | F2: 22 | H2: Piattaforma Unica Nazionale (MASE/GSE) del 17/09/2024, estratta da onData, CC BY 4.0 | I2: 2024-09-17 | J2: =IF(B2="","",IFERROR(INDEX(aree_servizio!B:B,MATCH(B2,aree_servizio!A:A,0)),"?")) | K2: =IF(C2="","",IFERROR(INDEX(gestori_ricarica!B:B,MATCH(C2,gestori_ricarica!A:A,0)),"?"))
A3: 3 | B3: 4 | C3: 1 | D3: 1 | E3: AC | F3: 22 | H3: Piattaforma Unica Nazionale (MASE/GSE) del 17/09/2024, estratta da onData, CC BY 4.0 | I3: 2024-09-17 | J3: =IF(B3="","",IFERROR(INDEX(aree_servizio!B:B,MATCH(B3,aree_servizio!A:A,0)),"?")) | K3: =IF(C3="","",IFERROR(INDEX(gestori_ricarica!B:B,MATCH(C3,gestori_ricarica!A:A,0)),"?"))
A4: 5 | B4: 6 | C4: 1 | D4: 4 | E4: DC | F4: 400 | H4: Piattaforma Unica Nazionale (MASE/GSE) del 17/09/2024, estratta da onData, CC BY 4.0 | I4: 2024-09-17 | J4: =IF(B4="","",IFERROR(INDEX(aree_servizio!B:B,MATCH(B4,aree_servizio!A:A,0)),"?")) | K4: =IF(C4="","",IFERROR(INDEX(gestori_ricarica!B:B,MATCH(C4,gestori_ricarica!A:A,0)),"?"))
A5: 6 | B5: 12 | C5: 1 | D5: 1 | E5: AC | F5: 22 | H5: Piattaforma Unica Nazionale (MASE/GSE) del 17/09/2024, estratta da onData, CC BY 4.0 | I5: 2024-09-17 | J5: =IF(B5="","",IFERROR(INDEX(aree_servizio!B:B,MATCH(B5,aree_servizio!A:A,0)),"?")) | K5: =IF(C5="","",IFERROR(INDEX(gestori_ricarica!B:B,MATCH(C5,gestori_ricarica!A:A,0)),"?"))
A6: 8 | B6: 13 | C6: 1 | D6: 1 | E6: AC | F6: 22 | H6: Piattaforma Unica Nazionale (MASE/GSE) del 17/09/2024, estratta da onData, CC BY 4.0 | I6: 2024-09-17 | J6: =IF(B6="","",IFERROR(INDEX(aree_servizio!B:B,MATCH(B6,aree_servizio!A:A,0)),"?")) | K6: =IF(C6="","",IFERROR(INDEX(gestori_ricarica!B:B,MATCH(C6,gestori_ricarica!A:A,0)),"?"))
A7: 10 | B7: 16 | C7: 1 | D7: 1 | E7: AC | F7: 22 | H7: Piattaforma Unica Nazionale (MASE/GSE) del 17/09/2024, estratta da onData, CC BY 4.0 | I7: 2024-09-17 | J7: =IF(B7="","",IFERROR(INDEX(aree_servizio!B:B,MATCH(B7,aree_servizio!A:A,0)),"?")) | K7: =IF(C7="","",IFERROR(INDEX(gestori_ricarica!B:B,MATCH(C7,gestori_ricarica!A:A,0)),"?"))
A8: 12 | B8: 18 | C8: 1 | D8: 1 | E8: AC | F8: 22 | H8: Piattaforma Unica Nazionale (MASE/GSE) del 17/09/2024, estratta da onData, CC BY 4.0 | I8: 2024-09-17 | J8: =IF(B8="","",IFERROR(INDEX(aree_servizio!B:B,MATCH(B8,aree_servizio!A:A,0)),"?")) | K8: =IF(C8="","",IFERROR(INDEX(gestori_ricarica!B:B,MATCH(C8,gestori_ricarica!A:A,0)),"?"))
A9: 14 | B9: 19 | C9: 1 | D9: 1 | E9: AC | F9: 22 | H9: Piattaforma Unica Nazionale (MASE/GSE) del 17/09/2024, estratta da onData, CC BY 4.0 | I9: 2024-09-17 | J9: =IF(B9="","",IFERROR(INDEX(aree_servizio!B:B,MATCH(B9,aree_servizio!A:A,0)),"?")) | K9: =IF(C9="","",IFERROR(INDEX(gestori_ricarica!B:B,MATCH(C9,gestori_ricarica!A:A,0)),"?"))
A10: 16 | B10: 20 | C10: 1 | D10: 1 | E10: AC | F10: 22 | H10: Piattaforma Unica Nazionale (MASE/GSE) del 17/09/2024, estratta da onData, CC BY 4.0 | I10: 2024-09-17 | J10: =IF(B10="","",IFERROR(INDEX(aree_servizio!B:B,MATCH(B10,aree_servizio!A:A,0)),"?")) | K10: =IF(C10="","",IFERROR(INDEX(gestori_ricarica!B:B,MATCH(C10,gestori_ricarica!A:A,0)),"?"))
A11: 18 | B11: 21 | C11: 1 | D11: 1 | E11: AC | F11: 22 | H11: Piattaforma Unica Nazionale (MASE/GSE) del 17/09/2024, estratta da onData, CC BY 4.0 | I11: 2024-09-17 | J11: =IF(B11="","",IFERROR(INDEX(aree_servizio!B:B,MATCH(B11,aree_servizio!A:A,0)),"?")) | K11: =IF(C11="","",IFERROR(INDEX(gestori_ricarica!B:B,MATCH(C11,gestori_ricarica!A:A,0)),"?"))
A12: 20 | B12: 23 | C12: 1 | D12: 1 | E12: AC | F12: 22 | H12: Piattaforma Unica Nazionale (MASE/GSE) del 17/09/2024, estratta da onData, CC BY 4.0 | I12: 2024-09-17 | J12: =IF(B12="","",IFERROR(INDEX(aree_servizio!B:B,MATCH(B12,aree_servizio!A:A,0)),"?")) | K12: =IF(C12="","",IFERROR(INDEX(gestori_ricarica!B:B,MATCH(C12,gestori_ricarica!A:A,0)),"?"))
A13: 22 | B13: 27 | C13: 1 | D13: 1 | E13: AC | F13: 22 | H13: Piattaforma Unica Nazionale (MASE/GSE) del 17/09/2024, estratta da onData, CC BY 4.0 | I13: 2024-09-17 | J13: =IF(B13="","",IFERROR(INDEX(aree_servizio!B:B,MATCH(B13,aree_servizio!A:A,0)),"?")) | K13: =IF(C13="","",IFERROR(INDEX(gestori_ricarica!B:B,MATCH(C13,gestori_ricarica!A:A,0)),"?"))
... A152: 260 | B152: 156 | C152: 15 | D152: 6 | E152: DC | F152: 150 | H152: Pagine Tesla 'Trova una stazione' (Supercharger Dorno Est e Dorno Ovest, Autogrill km 33 A7), consultate il 07/10/2026: 6 Supercharger, fino a 150 kW; in linea con l'elenco SmartWorld del 25/05/2023 | I152: 2026-10-07 | J152: =IF(B152="","",IFERROR(INDEX(aree_servizio!B:B,MATCH(B152,aree_servizio!A:A,0)),"?")) | K152: =IF(C152="","",IFERROR(INDEX(gestori_ricarica!B:B,MATCH(C152,gestori_ricarica!A:A,0)),"?"))
A153: 261 | B153: 3 | C153: 1 | E153: DC | H153: Elenco stampa Motorbox 'Mappa 2025 colonnine EV autostrada' (dati Motus-E/A2A): presenza segnalata, numero e potenza da confermare | J153: =IF(B153="","",IFERROR(INDEX(aree_servizio!B:B,MATCH(B153,aree_servizio!A:A,0)),"?")) | K153: =IF(C153="","",IFERROR(INDEX(gestori_ricarica!B:B,MATCH(C153,gestori_ricarica!A:A,0)),"?"))
A154: 262 | B154: 5 | C154: 1 | E154: DC | H154: Elenco stampa Motorbox 'Mappa 2025 colonnine EV autostrada' (dati Motus-E/A2A): presenza segnalata, numero e potenza da confermare | J154: =IF(B154="","",IFERROR(INDEX(aree_servizio!B:B,MATCH(B154,aree_servizio!A:A,0)),"?")) | K154: =IF(C154="","",IFERROR(INDEX(gestori_ricarica!B:B,MATCH(C154,gestori_ricarica!A:A,0)),"?"))
A155: 263 | B155: 50 | C155: 1 | E155: DC | H155: Elenco stampa Motorbox 'Mappa 2025 colonnine EV autostrada' (dati Motus-E/A2A): presenza segnalata, numero e potenza da confermare | J155: =IF(B155="","",IFERROR(INDEX(aree_servizio!B:B,MATCH(B155,aree_servizio!A:A,0)),"?")) | K155: =IF(C155="","",IFERROR(INDEX(gestori_ricarica!B:B,MATCH(C155,gestori_ricarica!A:A,0)),"?"))
A156: 264 | B156: 7 | C156: 1 | E156: DC | H156: Elenco stampa Motorbox 'Mappa 2025 colonnine EV autostrada' (dati Motus-E/A2A): presenza segnalata, numero e potenza da confermare | J156: =IF(B156="","",IFERROR(INDEX(aree_servizio!B:B,MATCH(B156,aree_servizio!A:A,0)),"?")) | K156: =IF(C156="","",IFERROR(INDEX(gestori_ricarica!B:B,MATCH(C156,gestori_ricarica!A:A,0)),"?"))
A157: 265 | B157: 48 | C157: 1 | E157: DC | H157: Elenco stampa Motorbox 'Mappa 2025 colonnine EV autostrada' (dati Motus-E/A2A): presenza segnalata, numero e potenza da confermare | J157: =IF(B157="","",IFERROR(INDEX(aree_servizio!B:B,MATCH(B157,aree_servizio!A:A,0)),"?")) | K157: =IF(C157="","",IFERROR(INDEX(gestori_ricarica!B:B,MATCH(C157,gestori_ricarica!A:A,0)),"?"))
A158: 266 | B158: 22 | C158: 1 | E158: DC | H158: Elenco stampa Motorbox 'Mappa 2025 colonnine EV autostrada' (dati Motus-E/A2A): presenza segnalata, numero e potenza da confermare | J158: =IF(B158="","",IFERROR(INDEX(aree_servizio!B:B,MATCH(B158,aree_servizio!A:A,0)),"?")) | K158: =IF(C158="","",IFERROR(INDEX(gestori_ricarica!B:B,MATCH(C158,gestori_ricarica!A:A,0)),"?"))
A159: 267 | B159: 32 | C159: 1 | E159: DC | H159: Elenco stampa Motorbox 'Mappa 2025 colonnine EV autostrada' (dati Motus-E/A2A): presenza segnalata, numero e potenza da confermare | J159: =IF(B159="","",IFERROR(INDEX(aree_servizio!B:B,MATCH(B159,aree_servizio!A:A,0)),"?")) | K159: =IF(C159="","",IFERROR(INDEX(gestori_ricarica!B:B,MATCH(C159,gestori_ricarica!A:A,0)),"?"))
A160: 268 | B160: 24 | C160: 1 | D160: 4 | E160: DC | F160: 300 | H160: Articolo Motorbox sull'inaugurazione della stazione Free To X di Teano Ovest (data dell'articolo non verificata): 4 prese in corrente continua fino a 300 kW; numero da confermare, assente dalla PUN del 17/09/2024 | J160: =IF(B160="","",IFERROR(INDEX(aree_servizio!B:B,MATCH(B160,aree_servizio!A:A,0)),"?")) | K160: =IF(C160="","",IFERROR(INDEX(gestori_ricarica!B:B,MATCH(C160,gestori_ricarica!A:A,0)),"?"))
A161: 269 | B161: 236 | C161: 1 | E161: DC | H161: Elenco stampa Motorbox 'Mappa 2025 colonnine EV autostrada' (dati Motus-E/A2A): presenza segnalata, numero e potenza da confermare | J161: =IF(B161="","",IFERROR(INDEX(aree_servizio!B:B,MATCH(B161,aree_servizio!A:A,0)),"?")) | K161: =IF(C161="","",IFERROR(INDEX(gestori_ricarica!B:B,MATCH(C161,gestori_ricarica!A:A,0)),"?"))
A162: 270 | B162: 249 | C162: 1 | E162: DC | H162: Elenco stampa Motorbox 'Mappa 2025 colonnine EV autostrada' (dati Motus-E/A2A): presenza segnalata, numero e potenza da confermare | J162: =IF(B162="","",IFERROR(INDEX(aree_servizio!B:B,MATCH(B162,aree_servizio!A:A,0)),"?")) | K162: =IF(C162="","",IFERROR(INDEX(gestori_ricarica!B:B,MATCH(C162,gestori_ricarica!A:A,0)),"?"))
A163: 271 | B163: 239 | C163: 1 | E163: DC | H163: Elenco stampa Motorbox 'Mappa 2025 colonnine EV autostrada' (dati Motus-E/A2A): presenza segnalata, numero e potenza da confermare | J163: =IF(B163="","",IFERROR(INDEX(aree_servizio!B:B,MATCH(B163,aree_servizio!A:A,0)),"?")) | K163: =IF(C163="","",IFERROR(INDEX(gestori_ricarica!B:B,MATCH(C163,gestori_ricarica!A:A,0)),"?"))
A164: 272 | B164: 246 | C164: 1 | E164: DC | H164: Elenco stampa Motorbox 'Mappa 2025 colonnine EV autostrada' (dati Motus-E/A2A): presenza segnalata, numero e potenza da confermare | J164: =IF(B164="","",IFERROR(INDEX(aree_servizio!B:B,MATCH(B164,aree_servizio!A:A,0)),"?")) | K164: =IF(C164="","",IFERROR(INDEX(gestori_ricarica!B:B,MATCH(C164,gestori_ricarica!A:A,0)),"?"))
A165: 273 | B165: 223 | C165: 1 | E165: DC | H165: Elenco stampa Motorbox 'Mappa 2025 colonnine EV autostrada' (dati Motus-E/A2A): presenza segnalata, numero e potenza da confermare | J165: =IF(B165="","",IFERROR(INDEX(aree_servizio!B:B,MATCH(B165,aree_servizio!A:A,0)),"?")) | K165: =IF(C165="","",IFERROR(INDEX(gestori_ricarica!B:B,MATCH(C165,gestori_ricarica!A:A,0)),"?"))
A166: 274 | B166: 262 | C166: 1 | E166: DC | H166: Elenco stampa Motorbox 'Mappa 2025 colonnine EV autostrada' (dati Motus-E/A2A): presenza segnalata, numero e potenza da confermare | J166: =IF(B166="","",IFERROR(INDEX(aree_servizio!B:B,MATCH(B166,aree_servizio!A:A,0)),"?")) | K166: =IF(C166="","",IFERROR(INDEX(gestori_ricarica!B:B,MATCH(C166,gestori_ricarica!A:A,0)),"?"))
A167: 275 | B167: 254 | C167: 1 | E167: DC | H167: Elenco stampa Motorbox 'Mappa 2025 colonnine EV autostrada' (dati Motus-E/A2A): presenza segnalata, numero e potenza da confermare | J167: =IF(B167="","",IFERROR(INDEX(aree_servizio!B:B,MATCH(B167,aree_servizio!A:A,0)),"?")) | K167: =IF(C167="","",IFERROR(INDEX(gestori_ricarica!B:B,MATCH(C167,gestori_ricarica!A:A,0)),"?"))
A168: 277 | B168: 145 | C168: 3 | E168: DC | H168: Elenco stampa Motorbox 'Mappa 2025 colonnine EV autostrada' (dati Motus-E/A2A): presenza segnalata, numero e potenza da confermare | J168: =IF(B168="","",IFERROR(INDEX(aree_servizio!B:B,MATCH(B168,aree_servizio!A:A,0)),"?")) | K168: =IF(C168="","",IFERROR(INDEX(gestori_ricarica!B:B,MATCH(C168,gestori_ricarica!A:A,0)),"?"))
A169: 278 | B169: 69 | C169: 3 | D169: 2 | E169: DC | F169: 50 | H169: PUN (MASE/GSE) del 17/09/2024 via onData, CC BY 4.0: sede "Autogrill Rosarno Est"; coerente con elenco Motorbox 2025 (Rosarno, direzione Salerno) | I169: 2024-09-17 | J169: =IF(B169="","",IFERROR(INDEX(aree_servizio!B:B,MATCH(B169,aree_servizio!A:A,0)),"?")) | K169: =IF(C169="","",IFERROR(INDEX(gestori_ricarica!B:B,MATCH(C169,gestori_ricarica!A:A,0)),"?"))
A170: 279 | B170: 69 | C170: 3 | D170: 3 | E170: AC | F170: 41 | H170: PUN (MASE/GSE) del 17/09/2024 via onData, CC BY 4.0: sede "Autogrill Rosarno Est"; coerente con elenco Motorbox 2025 (Rosarno, direzione Salerno) | I170: 2024-09-17 | J170: =IF(B170="","",IFERROR(INDEX(aree_servizio!B:B,MATCH(B170,aree_servizio!A:A,0)),"?")) | K170: =IF(C170="","",IFERROR(INDEX(gestori_ricarica!B:B,MATCH(C170,gestori_ricarica!A:A,0)),"?"))
A171: 280 | B171: 100 | C171: 16 | D171: 1 | E171: AC | F171: 22 | H171: Autovie Venete, punti di ricarica L. 178/2020, aggiornamento 01/10/2023 | I171: 2023-10-01 | J171: =IF(B171="","",IFERROR(INDEX(aree_servizio!B:B,MATCH(B171,aree_servizio!A:A,0)),"?")) | K171: =IF(C171="","",IFERROR(INDEX(gestori_ricarica!B:B,MATCH(C171,gestori_ricarica!A:A,0)),"?"))
A172: 297 | B172: 60 | C172: 21 | D172: 16 | E172: DC | F172: 60 | H172: App di ricarica (screenshot di Carlo del 07/10/2026): A2, 16 stazioni con codici IT_GES_..., tutte da 60 kW; gestore Go Electric Stations (codice GES); operatore Go Electric Stations confermato dall'app (scheda stazione) | I172: 2026-10-07 | J172: =IF(B172="","",IFERROR(INDEX(aree_servizio!B:B,MATCH(B172,aree_servizio!A:A,0)),"?")) | K172: =IF(C172="","",IFERROR(INDEX(gestori_ricarica!B:B,MATCH(C172,gestori_ricarica!A:A,0)),"?"))
A173: 298 | B173: 76 | C173: 21 | D173: 16 | E173: DC | F173: 60 | H173: App di ricarica (screenshot di Carlo del 07/10/2026): A2, 16 stazioni con codici IT_GES_..., tutte da 60 kW; gestore Go Electric Stations (codice GES); operatore Go Electric Stations confermato dall'app (scheda stazione) | I173: 2026-10-07 | J173: =IF(B173="","",IFERROR(INDEX(aree_servizio!B:B,MATCH(B173,aree_servizio!A:A,0)),"?")) | K173: =IF(C173="","",IFERROR(INDEX(gestori_ricarica!B:B,MATCH(C173,gestori_ricarica!A:A,0)),"?"))
A174: 299 | B174: 368 | C174: 1 | D174: 8 | E174: DC | F174: 300 | H174: App di ricarica (screenshot di Carlo del 07/10/2026): A26 Autostrada dei Trafori, Autogrill Stura, operatore Free To X; 5 colonnine: 4 da 300 kW e 1 da 66 kW; conteggio in punti di ricarica (2 prese per colonnina) | I174: 2026-10-07 | J174: =IF(B174="","",IFERROR(INDEX(aree_servizio!B:B,MATCH(B174,aree_servizio!A:A,0)),"?")) | K174: =IF(C174="","",IFERROR(INDEX(gestori_ricarica!B:B,MATCH(C174,gestori_ricarica!A:A,0)),"?"))
A175: 300 | B175: 368 | C175: 1 | D175: 2 | E175: DC | F175: 66 | H175: App di ricarica (screenshot di Carlo del 07/10/2026): A26 Autostrada dei Trafori, Autogrill Stura, operatore Free To X; 5 colonnine: 4 da 300 kW e 1 da 66 kW; conteggio in punti di ricarica (2 prese per colonnina) | I175: 2026-10-07 | J175: =IF(B175="","",IFERROR(INDEX(aree_servizio!B:B,MATCH(B175,aree_servizio!A:A,0)),"?")) | K175: =IF(C175="","",IFERROR(INDEX(gestori_ricarica!B:B,MATCH(C175,gestori_ricarica!A:A,0)),"?"))
A176: 301 | B176: 377 | C176: 1 | D176: 8 | E176: DC | F176: 300 | H176: App di ricarica, dati comunicati da Carlo il 07/10/2026: A26 Stura Ovest, operatore Free To X; 5 colonnine: 4 da 300 kW e 1 da 66 kW; conteggio in punti di ricarica (2 prese per colonnina) | I176: 2026-10-07 | J176: =IF(B176="","",IFERROR(INDEX(aree_servizio!B:B,MATCH(B176,aree_servizio!A:A,0)),"?")) | K176: =IF(C176="","",IFERROR(INDEX(gestori_ricarica!B:B,MATCH(C176,gestori_ricarica!A:A,0)),"?"))
A177: 302 | B177: 377 | C177: 1 | D177: 2 | E177: DC | F177: 66 | H177: App di ricarica, dati comunicati da Carlo il 07/10/2026: A26 Stura Ovest, operatore Free To X; 5 colonnine: 4 da 300 kW e 1 da 66 kW; conteggio in punti di ricarica (2 prese per colonnina) | I177: 2026-10-07 | J177: =IF(B177="","",IFERROR(INDEX(aree_servizio!B:B,MATCH(B177,aree_servizio!A:A,0)),"?")) | K177: =IF(C177="","",IFERROR(INDEX(gestori_ricarica!B:B,MATCH(C177,gestori_ricarica!A:A,0)),"?"))
A178: 303 | B178: 186 | C178: 1 | D178: 4 | E178: DC | F178: 300 | H178: App di ricarica (screenshot di Carlo del 07/10/2026): Peretola Sud, 'Autostrada Firenze Mare', 2 colonnine da 300 kW e 1 da 66 kW, due prese ciascuna = 6 punti DC; coerente con PUN 17/09/2024 | I178: 2026-10-07 | J178: =IF(B178="","",IFERROR(INDEX(aree_servizio!B:B,MATCH(B178,aree_servizio!A:A,0)),"?")) | K178: =IF(C178="","",IFERROR(INDEX(gestori_ricarica!B:B,MATCH(C178,gestori_ricarica!A:A,0)),"?"))
...

Sheet aree_marche_carburante
A1: id_area | B1: id_marca | C1: _area | D1: _marca
A2: 1 | B2: 3 | C2: =IF(A2="","",IFERROR(INDEX(aree_servizio!B:B,MATCH(A2,aree_servizio!A:A,0)),"?")) | D2: =IF(B2="","",IFERROR(INDEX(marche_carburante!B:B,MATCH(B2,marche_carburante!A:A,0)),"?"))
A3: 9 | B3: 9 | C3: =IF(A3="","",IFERROR(INDEX(aree_servizio!B:B,MATCH(A3,aree_servizio!A:A,0)),"?")) | D3: =IF(B3="","",IFERROR(INDEX(marche_carburante!B:B,MATCH(B3,marche_carburante!A:A,0)),"?"))
A4: 26 | B4: 12 | C4: =IF(A4="","",IFERROR(INDEX(aree_servizio!B:B,MATCH(A4,aree_servizio!A:A,0)),"?")) | D4: =IF(B4="","",IFERROR(INDEX(marche_carburante!B:B,MATCH(B4,marche_carburante!A:A,0)),"?"))
A5: 54 | B5: 3 | C5: =IF(A5="","",IFERROR(INDEX(aree_servizio!B:B,MATCH(A5,aree_servizio!A:A,0)),"?")) | D5: =IF(B5="","",IFERROR(INDEX(marche_carburante!B:B,MATCH(B5,marche_carburante!A:A,0)),"?"))
A6: 81 | B6: 5 | C6: =IF(A6="","",IFERROR(INDEX(aree_servizio!B:B,MATCH(A6,aree_servizio!A:A,0)),"?")) | D6: =IF(B6="","",IFERROR(INDEX(marche_carburante!B:B,MATCH(B6,marche_carburante!A:A,0)),"?"))
A7: 106 | B7: 12 | C7: =IF(A7="","",IFERROR(INDEX(aree_servizio!B:B,MATCH(A7,aree_servizio!A:A,0)),"?")) | D7: =IF(B7="","",IFERROR(INDEX(marche_carburante!B:B,MATCH(B7,marche_carburante!A:A,0)),"?"))
A8: 124 | B8: 15 | C8: =IF(A8="","",IFERROR(INDEX(aree_servizio!B:B,MATCH(A8,aree_servizio!A:A,0)),"?")) | D8: =IF(B8="","",IFERROR(INDEX(marche_carburante!B:B,MATCH(B8,marche_carburante!A:A,0)),"?"))
A9: 125 | B9: 1 | C9: =IF(A9="","",IFERROR(INDEX(aree_servizio!B:B,MATCH(A9,aree_servizio!A:A,0)),"?")) | D9: =IF(B9="","",IFERROR(INDEX(marche_carburante!B:B,MATCH(B9,marche_carburante!A:A,0)),"?"))
A10: 133 | B10: 6 | C10: =IF(A10="","",IFERROR(INDEX(aree_servizio!B:B,MATCH(A10,aree_servizio!A:A,0)),"?")) | D10: =IF(B10="","",IFERROR(INDEX(marche_carburante!B:B,MATCH(B10,marche_carburante!A:A,0)),"?"))
A11: 135 | B11: 15 | C11: =IF(A11="","",IFERROR(INDEX(aree_servizio!B:B,MATCH(A11,aree_servizio!A:A,0)),"?")) | D11: =IF(B11="","",IFERROR(INDEX(marche_carburante!B:B,MATCH(B11,marche_carburante!A:A,0)),"?"))
A12: 137 | B12: 12 | C12: =IF(A12="","",IFERROR(INDEX(aree_servizio!B:B,MATCH(A12,aree_servizio!A:A,0)),"?")) | D12: =IF(B12="","",IFERROR(INDEX(marche_carburante!B:B,MATCH(B12,marche_carburante!A:A,0)),"?"))
A13: 139 | B13: 11 | C13: =IF(A13="","",IFERROR(INDEX(aree_servizio!B:B,MATCH(A13,aree_servizio!A:A,0)),"?")) | D13: =IF(B13="","",IFERROR(INDEX(marche_carburante!B:B,MATCH(B13,marche_carburante!A:A,0)),"?"))
... A470: 480 | B470: 9 | C470: =IF(A470="","",IFERROR(INDEX(aree_servizio!B:B,MATCH(A470,aree_servizio!A:A,0)),"?")) | D470: =IF(B470="","",IFERROR(INDEX(marche_carburante!B:B,MATCH(B470,marche_carburante!A:A,0)),"?"))
C471: =IF(A471="","",IFERROR(INDEX(aree_servizio!B:B,MATCH(A471,aree_servizio!A:A,0)),"?")) | D471: =IF(B471="","",IFERROR(INDEX(marche_carburante!B:B,MATCH(B471,marche_carburante!A:A,0)),"?"))
C472: =IF(A472="","",IFERROR(INDEX(aree_servizio!B:B,MATCH(A472,aree_servizio!A:A,0)),"?")) | D472: =IF(B472="","",IFERROR(INDEX(marche_carburante!B:B,MATCH(B472,marche_carburante!A:A,0)),"?"))
C473: =IF(A473="","",IFERROR(INDEX(aree_servizio!B:B,MATCH(A473,aree_servizio!A:A,0)),"?")) | D473: =IF(B473="","",IFERROR(INDEX(marche_carburante!B:B,MATCH(B473,marche_carburante!A:A,0)),"?"))
C474: =IF(A474="","",IFERROR(INDEX(aree_servizio!B:B,MATCH(A474,aree_servizio!A:A,0)),"?")) | D474: =IF(B474="","",IFERROR(INDEX(marche_carburante!B:B,MATCH(B474,marche_carburante!A:A,0)),"?"))
C475: =IF(A475="","",IFERROR(INDEX(aree_servizio!B:B,MATCH(A475,aree_servizio!A:A,0)),"?")) | D475: =IF(B475="","",IFERROR(INDEX(marche_carburante!B:B,MATCH(B475,marche_carburante!A:A,0)),"?"))
C476: =IF(A476="","",IFERROR(INDEX(aree_servizio!B:B,MATCH(A476,aree_servizio!A:A,0)),"?")) | D476: =IF(B476="","",IFERROR(INDEX(marche_carburante!B:B,MATCH(B476,marche_carburante!A:A,0)),"?"))
C477: =IF(A477="","",IFERROR(INDEX(aree_servizio!B:B,MATCH(A477,aree_servizio!A:A,0)),"?")) | D477: =IF(B477="","",IFERROR(INDEX(marche_carburante!B:B,MATCH(B477,marche_carburante!A:A,0)),"?"))
C478: =IF(A478="","",IFERROR(INDEX(aree_servizio!B:B,MATCH(A478,aree_servizio!A:A,0)),"?")) | D478: =IF(B478="","",IFERROR(INDEX(marche_carburante!B:B,MATCH(B478,marche_carburante!A:A,0)),"?"))
C479: =IF(A479="","",IFERROR(INDEX(aree_servizio!B:B,MATCH(A479,aree_servizio!A:A,0)),"?")) | D479: =IF(B479="","",IFERROR(INDEX(marche_carburante!B:B,MATCH(B479,marche_carburante!A:A,0)),"?"))
C480: =IF(A480="","",IFERROR(INDEX(aree_servizio!B:B,MATCH(A480,aree_servizio!A:A,0)),"?")) | D480: =IF(B480="","",IFERROR(INDEX(marche_carburante!B:B,MATCH(B480,marche_carburante!A:A,0)),"?"))
C481: =IF(A481="","",IFERROR(INDEX(aree_servizio!B:B,MATCH(A481,aree_servizio!A:A,0)),"?")) | D481: =IF(B481="","",IFERROR(INDEX(marche_carburante!B:B,MATCH(B481,marche_carburante!A:A,0)),"?"))
C482: =IF(A482="","",IFERROR(INDEX(aree_servizio!B:B,MATCH(A482,aree_servizio!A:A,0)),"?")) | D482: =IF(B482="","",IFERROR(INDEX(marche_carburante!B:B,MATCH(B482,marche_carburante!A:A,0)),"?"))
... C620: =IF(A620="","",IFERROR(INDEX(aree_servizio!B:B,MATCH(A620,aree_servizio!A:A,0)),"?")) | D620: =IF(B620="","",IFERROR(INDEX(marche_carburante!B:B,MATCH(B620,marche_carburante!A:A,0)),"?"))

Sheet aree_marche_ristorante
A1: id_area | B1: id_marca | C1: _area | D1: _marca
A2: 1 | B2: 2 | C2: =IF(A2="","",IFERROR(INDEX(aree_servizio!B:B,MATCH(A2,aree_servizio!A:A,0)),"?")) | D2: =IF(B2="","",IFERROR(INDEX(marche_ristorante!B:B,MATCH(B2,marche_ristorante!A:A,0)),"?"))
A3: 2 | B3: 2 | C3: =IF(A3="","",IFERROR(INDEX(aree_servizio!B:B,MATCH(A3,aree_servizio!A:A,0)),"?")) | D3: =IF(B3="","",IFERROR(INDEX(marche_ristorante!B:B,MATCH(B3,marche_ristorante!A:A,0)),"?"))
A4: 2 | B4: 9 | C4: =IF(A4="","",IFERROR(INDEX(aree_servizio!B:B,MATCH(A4,aree_servizio!A:A,0)),"?")) | D4: =IF(B4="","",IFERROR(INDEX(marche_ristorante!B:B,MATCH(B4,marche_ristorante!A:A,0)),"?"))
A5: 3 | B5: 2 | C5: =IF(A5="","",IFERROR(INDEX(aree_servizio!B:B,MATCH(A5,aree_servizio!A:A,0)),"?")) | D5: =IF(B5="","",IFERROR(INDEX(marche_ristorante!B:B,MATCH(B5,marche_ristorante!A:A,0)),"?"))
A6: 4 | B6: 2 | C6: =IF(A6="","",IFERROR(INDEX(aree_servizio!B:B,MATCH(A6,aree_servizio!A:A,0)),"?")) | D6: =IF(B6="","",IFERROR(INDEX(marche_ristorante!B:B,MATCH(B6,marche_ristorante!A:A,0)),"?"))
A7: 4 | B7: 17 | C7: =IF(A7="","",IFERROR(INDEX(aree_servizio!B:B,MATCH(A7,aree_servizio!A:A,0)),"?")) | D7: =IF(B7="","",IFERROR(INDEX(marche_ristorante!B:B,MATCH(B7,marche_ristorante!A:A,0)),"?"))
A8: 5 | B8: 6 | C8: =IF(A8="","",IFERROR(INDEX(aree_servizio!B:B,MATCH(A8,aree_servizio!A:A,0)),"?")) | D8: =IF(B8="","",IFERROR(INDEX(marche_ristorante!B:B,MATCH(B8,marche_ristorante!A:A,0)),"?"))
A9: 6 | B9: 2 | C9: =IF(A9="","",IFERROR(INDEX(aree_servizio!B:B,MATCH(A9,aree_servizio!A:A,0)),"?")) | D9: =IF(B9="","",IFERROR(INDEX(marche_ristorante!B:B,MATCH(B9,marche_ristorante!A:A,0)),"?"))
A10: 6 | B10: 17 | C10: =IF(A10="","",IFERROR(INDEX(aree_servizio!B:B,MATCH(A10,aree_servizio!A:A,0)),"?")) | D10: =IF(B10="","",IFERROR(INDEX(marche_ristorante!B:B,MATCH(B10,marche_ristorante!A:A,0)),"?"))
A11: 7 | B11: 2 | C11: =IF(A11="","",IFERROR(INDEX(aree_servizio!B:B,MATCH(A11,aree_servizio!A:A,0)),"?")) | D11: =IF(B11="","",IFERROR(INDEX(marche_ristorante!B:B,MATCH(B11,marche_ristorante!A:A,0)),"?"))
A12: 8 | B12: 6 | C12: =IF(A12="","",IFERROR(INDEX(aree_servizio!B:B,MATCH(A12,aree_servizio!A:A,0)),"?")) | D12: =IF(B12="","",IFERROR(INDEX(marche_ristorante!B:B,MATCH(B12,marche_ristorante!A:A,0)),"?"))
A13: 9 | B13: 15 | C13: =IF(A13="","",IFERROR(INDEX(aree_servizio!B:B,MATCH(A13,aree_servizio!A:A,0)),"?")) | D13: =IF(B13="","",IFERROR(INDEX(marche_ristorante!B:B,MATCH(B13,marche_ristorante!A:A,0)),"?"))
... A427: 453 | B427: 6 | C427: =IF(A427="","",IFERROR(INDEX(aree_servizio!B:B,MATCH(A427,aree_servizio!A:A,0)),"?")) | D427: =IF(B427="","",IFERROR(INDEX(marche_ristorante!B:B,MATCH(B427,marche_ristorante!A:A,0)),"?"))
C428: =IF(A428="","",IFERROR(INDEX(aree_servizio!B:B,MATCH(A428,aree_servizio!A:A,0)),"?")) | D428: =IF(B428="","",IFERROR(INDEX(marche_ristorante!B:B,MATCH(B428,marche_ristorante!A:A,0)),"?"))
C429: =IF(A429="","",IFERROR(INDEX(aree_servizio!B:B,MATCH(A429,aree_servizio!A:A,0)),"?")) | D429: =IF(B429="","",IFERROR(INDEX(marche_ristorante!B:B,MATCH(B429,marche_ristorante!A:A,0)),"?"))
C430: =IF(A430="","",IFERROR(INDEX(aree_servizio!B:B,MATCH(A430,aree_servizio!A:A,0)),"?")) | D430: =IF(B430="","",IFERROR(INDEX(marche_ristorante!B:B,MATCH(B430,marche_ristorante!A:A,0)),"?"))
C431: =IF(A431="","",IFERROR(INDEX(aree_servizio!B:B,MATCH(A431,aree_servizio!A:A,0)),"?")) | D431: =IF(B431="","",IFERROR(INDEX(marche_ristorante!B:B,MATCH(B431,marche_ristorante!A:A,0)),"?"))
C432: =IF(A432="","",IFERROR(INDEX(aree_servizio!B:B,MATCH(A432,aree_servizio!A:A,0)),"?")) | D432: =IF(B432="","",IFERROR(INDEX(marche_ristorante!B:B,MATCH(B432,marche_ristorante!A:A,0)),"?"))
C433: =IF(A433="","",IFERROR(INDEX(aree_servizio!B:B,MATCH(A433,aree_servizio!A:A,0)),"?")) | D433: =IF(B433="","",IFERROR(INDEX(marche_ristorante!B:B,MATCH(B433,marche_ristorante!A:A,0)),"?"))
C434: =IF(A434="","",IFERROR(INDEX(aree_servizio!B:B,MATCH(A434,aree_servizio!A:A,0)),"?")) | D434: =IF(B434="","",IFERROR(INDEX(marche_ristorante!B:B,MATCH(B434,marche_ristorante!A:A,0)),"?"))
C435: =IF(A435="","",IFERROR(INDEX(aree_servizio!B:B,MATCH(A435,aree_servizio!A:A,0)),"?")) | D435: =IF(B435="","",IFERROR(INDEX(marche_ristorante!B:B,MATCH(B435,marche_ristorante!A:A,0)),"?"))
C436: =IF(A436="","",IFERROR(INDEX(aree_servizio!B:B,MATCH(A436,aree_servizio!A:A,0)),"?")) | D436: =IF(B436="","",IFERROR(INDEX(marche_ristorante!B:B,MATCH(B436,marche_ristorante!A:A,0)),"?"))
C437: =IF(A437="","",IFERROR(INDEX(aree_servizio!B:B,MATCH(A437,aree_servizio!A:A,0)),"?")) | D437: =IF(B437="","",IFERROR(INDEX(marche_ristorante!B:B,MATCH(B437,marche_ristorante!A:A,0)),"?"))
C438: =IF(A438="","",IFERROR(INDEX(aree_servizio!B:B,MATCH(A438,aree_servizio!A:A,0)),"?")) | D438: =IF(B438="","",IFERROR(INDEX(marche_ristorante!B:B,MATCH(B438,marche_ristorante!A:A,0)),"?"))
C439: =IF(A439="","",IFERROR(INDEX(aree_servizio!B:B,MATCH(A439,aree_servizio!A:A,0)),"?")) | D439: =IF(B439="","",IFERROR(INDEX(marche_ristorante!B:B,MATCH(B439,marche_ristorante!A:A,0)),"?"))
... C577: =IF(A577="","",IFERROR(INDEX(aree_servizio!B:B,MATCH(A577,aree_servizio!A:A,0)),"?")) | D577: =IF(B577="","",IFERROR(INDEX(marche_ristorante!B:B,MATCH(B577,marche_ristorante!A:A,0)),"?"))

Sheet aree_servizi
A1: id_area | B1: id_servizio | C1: _area | D1: _servizio
A2: 1 | B2: 5 | C2: =IF(A2="","",IFERROR(INDEX(aree_servizio!B:B,MATCH(A2,aree_servizio!A:A,0)),"?")) | D2: =IF(B2="","",IFERROR(INDEX(servizi!B:B,MATCH(B2,servizi!A:A,0)),"?"))
A3: 1 | B3: 12 | C3: =IF(A3="","",IFERROR(INDEX(aree_servizio!B:B,MATCH(A3,aree_servizio!A:A,0)),"?")) | D3: =IF(B3="","",IFERROR(INDEX(servizi!B:B,MATCH(B3,servizi!A:A,0)),"?"))
A4: 1 | B4: 26 | C4: =IF(A4="","",IFERROR(INDEX(aree_servizio!B:B,MATCH(A4,aree_servizio!A:A,0)),"?")) | D4: =IF(B4="","",IFERROR(INDEX(servizi!B:B,MATCH(B4,servizi!A:A,0)),"?"))
A5: 2 | B5: 5 | C5: =IF(A5="","",IFERROR(INDEX(aree_servizio!B:B,MATCH(A5,aree_servizio!A:A,0)),"?")) | D5: =IF(B5="","",IFERROR(INDEX(servizi!B:B,MATCH(B5,servizi!A:A,0)),"?"))
A6: 2 | B6: 25 | C6: =IF(A6="","",IFERROR(INDEX(aree_servizio!B:B,MATCH(A6,aree_servizio!A:A,0)),"?")) | D6: =IF(B6="","",IFERROR(INDEX(servizi!B:B,MATCH(B6,servizi!A:A,0)),"?"))
A7: 2 | B7: 12 | C7: =IF(A7="","",IFERROR(INDEX(aree_servizio!B:B,MATCH(A7,aree_servizio!A:A,0)),"?")) | D7: =IF(B7="","",IFERROR(INDEX(servizi!B:B,MATCH(B7,servizi!A:A,0)),"?"))
A8: 2 | B8: 14 | C8: =IF(A8="","",IFERROR(INDEX(aree_servizio!B:B,MATCH(A8,aree_servizio!A:A,0)),"?")) | D8: =IF(B8="","",IFERROR(INDEX(servizi!B:B,MATCH(B8,servizi!A:A,0)),"?"))
A9: 2 | B9: 28 | C9: =IF(A9="","",IFERROR(INDEX(aree_servizio!B:B,MATCH(A9,aree_servizio!A:A,0)),"?")) | D9: =IF(B9="","",IFERROR(INDEX(servizi!B:B,MATCH(B9,servizi!A:A,0)),"?"))
A10: 2 | B10: 13 | C10: =IF(A10="","",IFERROR(INDEX(aree_servizio!B:B,MATCH(A10,aree_servizio!A:A,0)),"?")) | D10: =IF(B10="","",IFERROR(INDEX(servizi!B:B,MATCH(B10,servizi!A:A,0)),"?"))
A11: 2 | B11: 4 | C11: =IF(A11="","",IFERROR(INDEX(aree_servizio!B:B,MATCH(A11,aree_servizio!A:A,0)),"?")) | D11: =IF(B11="","",IFERROR(INDEX(servizi!B:B,MATCH(B11,servizi!A:A,0)),"?"))
A12: 2 | B12: 15 | C12: =IF(A12="","",IFERROR(INDEX(aree_servizio!B:B,MATCH(A12,aree_servizio!A:A,0)),"?")) | D12: =IF(B12="","",IFERROR(INDEX(servizi!B:B,MATCH(B12,servizi!A:A,0)),"?"))
A13: 2 | B13: 27 | C13: =IF(A13="","",IFERROR(INDEX(aree_servizio!B:B,MATCH(A13,aree_servizio!A:A,0)),"?")) | D13: =IF(B13="","",IFERROR(INDEX(servizi!B:B,MATCH(B13,servizi!A:A,0)),"?"))
... A2532: 427 | B2532: 26 | C2532: =IF(A2532="","",IFERROR(INDEX(aree_servizio!B:B,MATCH(A2532,aree_servizio!A:A,0)),"?")) | D2532: =IF(B2532="","",IFERROR(INDEX(servizi!B:B,MATCH(B2532,servizi!A:A,0)),"?"))
C2533: =IF(A2533="","",IFERROR(INDEX(aree_servizio!B:B,MATCH(A2533,aree_servizio!A:A,0)),"?")) | D2533: =IF(B2533="","",IFERROR(INDEX(servizi!B:B,MATCH(B2533,servizi!A:A,0)),"?"))
C2534: =IF(A2534="","",IFERROR(INDEX(aree_servizio!B:B,MATCH(A2534,aree_servizio!A:A,0)),"?")) | D2534: =IF(B2534="","",IFERROR(INDEX(servizi!B:B,MATCH(B2534,servizi!A:A,0)),"?"))
C2535: =IF(A2535="","",IFERROR(INDEX(aree_servizio!B:B,MATCH(A2535,aree_servizio!A:A,0)),"?")) | D2535: =IF(B2535="","",IFERROR(INDEX(servizi!B:B,MATCH(B2535,servizi!A:A,0)),"?"))
C2536: =IF(A2536="","",IFERROR(INDEX(aree_servizio!B:B,MATCH(A2536,aree_servizio!A:A,0)),"?")) | D2536: =IF(B2536="","",IFERROR(INDEX(servizi!B:B,MATCH(B2536,servizi!A:A,0)),"?"))
C2537: =IF(A2537="","",IFERROR(INDEX(aree_servizio!B:B,MATCH(A2537,aree_servizio!A:A,0)),"?")) | D2537: =IF(B2537="","",IFERROR(INDEX(servizi!B:B,MATCH(B2537,servizi!A:A,0)),"?"))
C2538: =IF(A2538="","",IFERROR(INDEX(aree_servizio!B:B,MATCH(A2538,aree_servizio!A:A,0)),"?")) | D2538: =IF(B2538="","",IFERROR(INDEX(servizi!B:B,MATCH(B2538,servizi!A:A,0)),"?"))
C2539: =IF(A2539="","",IFERROR(INDEX(aree_servizio!B:B,MATCH(A2539,aree_servizio!A:A,0)),"?")) | D2539: =IF(B2539="","",IFERROR(INDEX(servizi!B:B,MATCH(B2539,servizi!A:A,0)),"?"))
C2540: =IF(A2540="","",IFERROR(INDEX(aree_servizio!B:B,MATCH(A2540,aree_servizio!A:A,0)),"?")) | D2540: =IF(B2540="","",IFERROR(INDEX(servizi!B:B,MATCH(B2540,servizi!A:A,0)),"?"))
C2541: =IF(A2541="","",IFERROR(INDEX(aree_servizio!B:B,MATCH(A2541,aree_servizio!A:A,0)),"?")) | D2541: =IF(B2541="","",IFERROR(INDEX(servizi!B:B,MATCH(B2541,servizi!A:A,0)),"?"))
C2542: =IF(A2542="","",IFERROR(INDEX(aree_servizio!B:B,MATCH(A2542,aree_servizio!A:A,0)),"?")) | D2542: =IF(B2542="","",IFERROR(INDEX(servizi!B:B,MATCH(B2542,servizi!A:A,0)),"?"))
C2543: =IF(A2543="","",IFERROR(INDEX(aree_servizio!B:B,MATCH(A2543,aree_servizio!A:A,0)),"?")) | D2543: =IF(B2543="","",IFERROR(INDEX(servizi!B:B,MATCH(B2543,servizi!A:A,0)),"?"))
C2544: =IF(A2544="","",IFERROR(INDEX(aree_servizio!B:B,MATCH(A2544,aree_servizio!A:A,0)),"?")) | D2544: =IF(B2544="","",IFERROR(INDEX(servizi!B:B,MATCH(B2544,servizi!A:A,0)),"?"))
... C2682: =IF(A2682="","",IFERROR(INDEX(aree_servizio!B:B,MATCH(A2682,aree_servizio!A:A,0)),"?")) | D2682: =IF(B2682="","",IFERROR(INDEX(servizi!B:B,MATCH(B2682,servizi!A:A,0)),"?"))

Sheet aree_servizio
A1: id | B1: nome | C1: lat | D1: lon | E1: id_autostrada | F1: id_casello_direzione | G1: km | H1: lato | I1: attiva_2026 | J1: fonte_coordinate | K1: stato | L1: km_cippo | M1: _autostrada | N1: _direzione
A2: 1 | B2: S.Donato Ovest | C2: 45.42169 | D2: 9.251035 | E2: 1 | F2: 3 | G2: 0 | H2: Ovest | I2: -1 | J2: originale | K2: aperta | L2: 0 | M2: =IF(E2="","",IFERROR(INDEX(autostrade!B:B,MATCH(E2,autostrade!A:A,0)),"?")) | N2: =IF(F2="","",IFERROR(INDEX(caselli!B:B,MATCH(F2,caselli!A:A,0)),"?"))
A3: 2 | B3: S. Zenone Ovest | C3: 45.320415 | D3: 9.376749 | E3: 1 | F3: 3 | G3: 15.1 | H3: Ovest | I3: 1 | J3: originale | K3: aperta | L3: 15.1 | M3: =IF(E3="","",IFERROR(INDEX(autostrade!B:B,MATCH(E3,autostrade!A:A,0)),"?")) | N3: =IF(F3="","",IFERROR(INDEX(caselli!B:B,MATCH(F3,caselli!A:A,0)),"?"))
A4: 3 | B4: Somaglia Ovest | C4: 45.14197 | D4: 9.6340094 | E4: 1 | F4: 3 | G4: 43.5 | H4: Ovest | I4: 1 | J4: ministero | K4: aperta | L4: 43.5 | M4: =IF(E4="","",IFERROR(INDEX(autostrade!B:B,MATCH(E4,autostrade!A:A,0)),"?")) | N4: =IF(F4="","",IFERROR(INDEX(caselli!B:B,MATCH(F4,caselli!A:A,0)),"?"))
A5: 4 | B5: Arda Ovest | C5: 44.962295 | D5: 9.90515 | E5: 1 | F5: 3 | G5: 73.3 | H5: Ovest | I5: 1 | J5: originale | K5: aperta | L5: 73.3 | M5: =IF(E5="","",IFERROR(INDEX(autostrade!B:B,MATCH(E5,autostrade!A:A,0)),"?")) | N5: =IF(F5="","",IFERROR(INDEX(caselli!B:B,MATCH(F5,caselli!A:A,0)),"?"))
A6: 5 | B6: S.Martino Ovest | C6: 44.826034 | D6: 10.379451 | E6: 1 | F6: 3 | G6: 114.1 | H6: Ovest | I6: 1 | J6: originale | K6: aperta | L6: 114.1 | M6: =IF(E6="","",IFERROR(INDEX(autostrade!B:B,MATCH(E6,autostrade!A:A,0)),"?")) | N6: =IF(F6="","",IFERROR(INDEX(caselli!B:B,MATCH(F6,caselli!A:A,0)),"?"))
A7: 6 | B7: Secchia Ovest | C7: 44.661608 | D7: 10.856611 | E7: 1 | F7: 3 | G7: 156.5 | H7: Ovest | I7: 1 | J7: originale | K7: aperta | L7: 156.5 | M7: =IF(E7="","",IFERROR(INDEX(autostrade!B:B,MATCH(E7,autostrade!A:A,0)),"?")) | N7: =IF(F7="","",IFERROR(INDEX(caselli!B:B,MATCH(F7,caselli!A:A,0)),"?"))
A8: 7 | B8: Cantagallo Ovest | C8: 44.45601 | D8: 11.279817 | E8: 1 | F8: 3 | G8: 198.9 | H8: Ovest | I8: 1 | J8: originale | K8: aperta | L8: 198.9 | M8: =IF(E8="","",IFERROR(INDEX(autostrade!B:B,MATCH(E8,autostrade!A:A,0)),"?")) | N8: =IF(F8="","",IFERROR(INDEX(caselli!B:B,MATCH(F8,caselli!A:A,0)),"?"))
A9: 8 | B9: Roncobilaccio Ovest | C9: 44.116314 | D9: 11.231144 | E9: 1 | F9: 3 | G9: 242.6 | H9: Ovest | I9: 1 | J9: originale | K9: aperta | L9: 242.6 | M9: =IF(E9="","",IFERROR(INDEX(autostrade!B:B,MATCH(E9,autostrade!A:A,0)),"?")) | N9: =IF(F9="","",IFERROR(INDEX(caselli!B:B,MATCH(F9,caselli!A:A,0)),"?"))
A10: 9 | B10: Aglio Ovest | C10: 44.032672 | D10: 11.224823 | E10: 1 | F10: 3 | G10: 255.4 | H10: Ovest | I10: -1 | J10: originale | K10: aperta | L10: 255.4 | M10: =IF(E10="","",IFERROR(INDEX(autostrade!B:B,MATCH(E10,autostrade!A:A,0)),"?")) | N10: =IF(F10="","",IFERROR(INDEX(caselli!B:B,MATCH(F10,caselli!A:A,0)),"?"))
A11: 10 | B11: Bisenzio Ovest | C11: 43.83955 | D11: 11.162026 | E11: 1 | F11: 3 | G11: 279.8 | H11: Ovest | I11: 1 | J11: originale | K11: aperta | L11: 279.8 | M11: =IF(E11="","",IFERROR(INDEX(autostrade!B:B,MATCH(E11,autostrade!A:A,0)),"?")) | N11: =IF(F11="","",IFERROR(INDEX(caselli!B:B,MATCH(F11,caselli!A:A,0)),"?"))
A12: 11 | B12: Chianti Ovest | C12: 43.729398 | D12: 11.333529 | E12: 1 | F12: 3 | G12: 305.6 | H12: Ovest | I12: 1 | J12: originale | K12: aperta | L12: 305.6 | M12: =IF(E12="","",IFERROR(INDEX(autostrade!B:B,MATCH(E12,autostrade!A:A,0)),"?")) | N12: =IF(F12="","",IFERROR(INDEX(caselli!B:B,MATCH(F12,caselli!A:A,0)),"?"))
A13: 12 | B13: Arno Ovest | C13: 43.650041 | D13: 11.464536 | E13: 1 | F13: 3 | G13: 321.5 | H13: Ovest | I13: 1 | J13: originale | K13: aperta | L13: 321.5 | M13: =IF(E13="","",IFERROR(INDEX(autostrade!B:B,MATCH(E13,autostrade!A:A,0)),"?")) | N13: =IF(F13="","",IFERROR(INDEX(caselli!B:B,MATCH(F13,caselli!A:A,0)),"?"))
... A27: 26 | B27: Masseria Ovest | C27: 40.89103 | D27: 14.31693 | E27: 1 | F27: 3 | G27: 754 | H27: Ovest | I27: 1 | J27: google_maps | K27: chiusa (temporaneamente) | L27: 754 | M27: =IF(E27="","",IFERROR(INDEX(autostrade!B:B,MATCH(E27,autostrade!A:A,0)),"?")) | N27: =IF(F27="","",IFERROR(INDEX(caselli!B:B,MATCH(F27,caselli!A:A,0)),"?"))
A28: 27 | B28: Cittadella | C28: 40.886338 | D28: 14.316955 | E28: 1 | F28: 3 | G28: 755.7 | I28: 1 | J28: originale | K28: aperta | L28: 755.7 | M28: =IF(E28="","",IFERROR(INDEX(autostrade!B:B,MATCH(E28,autostrade!A:A,0)),"?")) | N28: =IF(F28="","",IFERROR(INDEX(caselli!B:B,MATCH(F28,caselli!A:A,0)),"?"))
A29: 28 | B29: Masseria Est | C29: 40.8921 | D29: 14.318813 | E29: 1 | F29: 1 | G29: 0 | H29: Est | I29: 1 | J29: originale | K29: aperta | L29: 753.1 | M29: =IF(E29="","",IFERROR(INDEX(autostrade!B:B,MATCH(E29,autostrade!A:A,0)),"?")) | N29: =IF(F29="","",IFERROR(INDEX(caselli!B:B,MATCH(F29,caselli!A:A,0)),"?"))
A30: 29 | B30: S. Nicola Est | C30: 41.05062 | D30: 14.322512 | E30: 1 | F30: 1 | G30: 16 | H30: Est | I30: 1 | J30: originale | K30: aperta | L30: 737.1 | M30: =IF(E30="","",IFERROR(INDEX(autostrade!B:B,MATCH(E30,autostrade!A:A,0)),"?")) | N30: =IF(F30="","",IFERROR(INDEX(caselli!B:B,MATCH(F30,caselli!A:A,0)),"?"))
A31: 30 | B31: Teano Est | C31: 41.234955 | D31: 14.093042 | E31: 1 | F31: 1 | G31: 45 | H31: Est | I31: 1 | J31: originale | K31: aperta | L31: 708.1 | M31: =IF(E31="","",IFERROR(INDEX(autostrade!B:B,MATCH(E31,autostrade!A:A,0)),"?")) | N31: =IF(F31="","",IFERROR(INDEX(caselli!B:B,MATCH(F31,caselli!A:A,0)),"?"))
A32: 31 | B32: Casilina Est | C32: 41.497471 | D32: 13.683434 | E32: 1 | F32: 1 | G32: 93 | H32: Est | I32: 1 | J32: originale | K32: aperta | L32: 660.1 | M32: =IF(E32="","",IFERROR(INDEX(autostrade!B:B,MATCH(E32,autostrade!A:A,0)),"?")) | N32: =IF(F32="","",IFERROR(INDEX(caselli!B:B,MATCH(F32,caselli!A:A,0)),"?"))
A33: 32 | B33: La Macchia Est | C33: 41.685933 | D33: 13.189461 | E33: 1 | F33: 1 | G33: 140 | H33: Est | I33: 1 | J33: originale | K33: aperta | L33: 613.1 | M33: =IF(E33="","",IFERROR(INDEX(autostrade!B:B,MATCH(E33,autostrade!A:A,0)),"?")) | N33: =IF(F33="","",IFERROR(INDEX(caselli!B:B,MATCH(F33,caselli!A:A,0)),"?"))
A34: 33 | B34: Prenestina Est | C34: 41.892398 | D34: 12.757634 | E34: 1 | F34: 1 | G34: 187 | H34: Est | I34: 1 | J34: originale | K34: aperta | L34: 566.1 | M34: =IF(E34="","",IFERROR(INDEX(autostrade!B:B,MATCH(E34,autostrade!A:A,0)),"?")) | N34: =IF(F34="","",IFERROR(INDEX(caselli!B:B,MATCH(F34,caselli!A:A,0)),"?"))
A35: 34 | B35: Mascherone Est | C35: 42.124321 | D35: 12.617774 | E35: 1 | F35: 1 | G35: 217 | H35: Est | I35: 1 | J35: originale | K35: aperta | L35: 536.1 | M35: =IF(E35="","",IFERROR(INDEX(autostrade!B:B,MATCH(E35,autostrade!A:A,0)),"?")) | N35: =IF(F35="","",IFERROR(INDEX(caselli!B:B,MATCH(F35,caselli!A:A,0)),"?"))
A36: 35 | B36: Flaminia Est | C36: 42.317009 | D36: 12.492393 | E36: 1 | F36: 1 | G36: 244 | H36: Est | I36: 1 | J36: originale | K36: aperta | L36: 509.1 | M36: =IF(E36="","",IFERROR(INDEX(autostrade!B:B,MATCH(E36,autostrade!A:A,0)),"?")) | N36: =IF(F36="","",IFERROR(INDEX(caselli!B:B,MATCH(F36,caselli!A:A,0)),"?"))
A37: 36 | B37: Giove Est | C37: 42.500532 | D37: 12.31175 | E37: 1 | F37: 1 | G37: 272 | H37: Est | I37: 1 | J37: originale | K37: aperta | L37: 481.1 | M37: =IF(E37="","",IFERROR(INDEX(autostrade!B:B,MATCH(E37,autostrade!A:A,0)),"?")) | N37: =IF(F37="","",IFERROR(INDEX(caselli!B:B,MATCH(F37,caselli!A:A,0)),"?"))
A38: 37 | B38: Tevere Est | C38: 42.625959 | D38: 12.231351 | E38: 1 | F38: 1 | G38: 288 | H38: Est | I38: 1 | J38: originale | K38: aperta | L38: 465.1 | M38: =IF(E38="","",IFERROR(INDEX(autostrade!B:B,MATCH(E38,autostrade!A:A,0)),"?")) | N38: =IF(F38="","",IFERROR(INDEX(caselli!B:B,MATCH(F38,caselli!A:A,0)),"?"))
A39: 38 | B39: Fabbro Est | C39: 42.876316 | D39: 12.018704 | E39: 1 | F39: 1 | G39: 326.2 | H39: Est | I39: 1 | J39: originale | K39: aperta | L39: 426.9 | M39: =IF(E39="","",IFERROR(INDEX(autostrade!B:B,MATCH(E39,autostrade!A:A,0)),"?")) | N39: =IF(F39="","",IFERROR(INDEX(caselli!B:B,MATCH(F39,caselli!A:A,0)),"?"))
A40: 39 | B40: Montepulciano Est | C40: 43.137152 | D40: 11.864536 | E40: 1 | F40: 1 | G40: 358 | H40: Est | I40: 1 | J40: originale | K40: aperta | L40: 395.1 | M40: =IF(E40="","",IFERROR(INDEX(autostrade!B:B,MATCH(E40,autostrade!A:A,0)),"?")) | N40: =IF(F40="","",IFERROR(INDEX(caselli!B:B,MATCH(F40,caselli!A:A,0)),"?"))
... A44: 43 | B44: Chianti Est | C44: 43.730077 | D44: 11.33239 | E44: 1 | F44: 1 | G44: 448 | H44: Est | I44: 1 | J44: originale | K44: aperta | L44: 305.1 | M44: =IF(E44="","",IFERROR(INDEX(autostrade!B:B,MATCH(E44,autostrade!A:A,0)),"?")) | N44: =IF(F44="","",IFERROR(INDEX(caselli!B:B,MATCH(F44,caselli!A:A,0)),"?"))
A45: 44 | B45: Firenze Nord | C45: 43.833023 | D45: 11.16018 | H45: Nord | I45: -1 | J45: google_maps | K45: aperta | M45: =IF(E45="","",IFERROR(INDEX(autostrade!B:B,MATCH(E45,autostrade!A:A,0)),"?")) | N45: =IF(F45="","",IFERROR(INDEX(caselli!B:B,MATCH(F45,caselli!A:A,0)),"?"))
A46: 45 | B46: Bisenzio Est | C46: 43.835524 | D46: 11.160042 | E46: 1 | F46: 1 | G46: 474 | H46: Est | I46: 1 | J46: google_maps | K46: aperta | L46: 279.1 | M46: =IF(E46="","",IFERROR(INDEX(autostrade!B:B,MATCH(E46,autostrade!A:A,0)),"?")) | N46: =IF(F46="","",IFERROR(INDEX(caselli!B:B,MATCH(F46,caselli!A:A,0)),"?"))
A47: 46 | B47: Aglio Est | C47: 44.028935 | D47: 11.225672 | E47: 1 | F47: 1 | G47: 497 | H47: Est | I47: 1 | J47: google_maps | K47: aperta | L47: 256.1 | M47: =IF(E47="","",IFERROR(INDEX(autostrade!B:B,MATCH(E47,autostrade!A:A,0)),"?")) | N47: =IF(F47="","",IFERROR(INDEX(caselli!B:B,MATCH(F47,caselli!A:A,0)),"?"))
A48: 47 | B48: Roncobilaccio Est | C48: 44.116584 | D48: 11.231874 | E48: 1 | F48: 1 | G48: 511 | H48: Est | I48: 1 | J48: originale | K48: aperta | L48: 242.1 | M48: =IF(E48="","",IFERROR(INDEX(autostrade!B:B,MATCH(E48,autostrade!A:A,0)),"?")) | N48: =IF(F48="","",IFERROR(INDEX(caselli!B:B,MATCH(F48,caselli!A:A,0)),"?"))
A49: 48 | B49: Cantagallo Est | C49: 44.457096 | D49: 11.280967 | E49: 1 | F49: 1 | G49: 554 | H49: Est | I49: 1 | J49: originale | K49: aperta | L49: 199.1 | M49: =IF(E49="","",IFERROR(INDEX(autostrade!B:B,MATCH(E49,autostrade!A:A,0)),"?")) | N49: =IF(F49="","",IFERROR(INDEX(caselli!B:B,MATCH(F49,caselli!A:A,0)),"?"))
A50: 49 | B50: Secchia Est | C50: 44.663146 | D50: 10.856207 | E50: 1 | F50: 1 | G50: 597 | H50: Est | I50: 1 | J50: originale | K50: aperta | L50: 156.1 | M50: =IF(E50="","",IFERROR(INDEX(autostrade!B:B,MATCH(E50,autostrade!A:A,0)),"?")) | N50: =IF(F50="","",IFERROR(INDEX(caselli!B:B,MATCH(F50,caselli!A:A,0)),"?"))
A51: 50 | B51: S.Martino Est | C51: 44.827578 | D51: 10.378118 | E51: 1 | F51: 1 | G51: 639 | H51: Est | I51: 1 | J51: originale | K51: aperta | L51: 114.1 | M51: =IF(E51="","",IFERROR(INDEX(autostrade!B:B,MATCH(E51,autostrade!A:A,0)),"?")) | N51: =IF(F51="","",IFERROR(INDEX(caselli!B:B,MATCH(F51,caselli!A:A,0)),"?"))
A52: 51 | B52: Arda Est | C52: 44.963366 | D52: 9.904833 | E52: 1 | F52: 1 | G52: 680 | H52: Est | I52: 1 | J52: originale | K52: aperta | L52: 73.1 | M52: =IF(E52="","",IFERROR(INDEX(autostrade!B:B,MATCH(E52,autostrade!A:A,0)),"?")) | N52: =IF(F52="","",IFERROR(INDEX(caselli!B:B,MATCH(F52,caselli!A:A,0)),"?"))
A53: 52 | B53: Somaglia Est | C53: 45.143142 | D53: 9.633814 | E53: 1 | F53: 1 | G53: 710 | H53: Est | I53: 1 | J53: originale | K53: aperta | L53: 43.1 | M53: =IF(E53="","",IFERROR(INDEX(autostrade!B:B,MATCH(E53,autostrade!A:A,0)),"?")) | N53: =IF(F53="","",IFERROR(INDEX(caselli!B:B,MATCH(F53,caselli!A:A,0)),"?"))
A54: 53 | B54: S. Zenone Est | C54: 45.322382 | D54: 9.375556 | E54: 1 | F54: 1 | G54: 738 | H54: Est | I54: 1 | J54: originale | K54: aperta | L54: 15.1 | M54: =IF(E54="","",IFERROR(INDEX(autostrade!B:B,MATCH(E54,autostrade!A:A,0)),"?")) | N54: =IF(F54="","",IFERROR(INDEX(caselli!B:B,MATCH(F54,caselli!A:A,0)),"?"))
A55: 54 | B55: S. Donato Est | C55: 45.422255 | D55: 9.251761 | E55: 1 | F55: 1 | G55: 753 | H55: Est | I55: -1 | J55: originale | K55: aperta | L55: 0.1 | M55: =IF(E55="","",IFERROR(INDEX(autostrade!B:B,MATCH(E55,autostrade!A:A,0)),"?")) | N55: =IF(F55="","",IFERROR(INDEX(caselli!B:B,MATCH(F55,caselli!A:A,0)),"?"))
A56: 55 | B56: Torre Annunziata Ovest | C56: 40.751763 | D56: 14.471662 | E56: 3 | F56: 58 | G56: 21.3 | H56: Ovest | I56: 1 | J56: originale | K56: aperta | L56: 21.3 | M56: =IF(E56="","",IFERROR(INDEX(autostrade!B:B,MATCH(E56,autostrade!A:A,0)),"?")) | N56: =IF(F56="","",IFERROR(INDEX(caselli!B:B,MATCH(F56,caselli!A:A,0)),"?"))
...

Sheet autostrade
A1: id | B1: sigla | C1: tratta_europea | D1: nome | E1: id_casello_inizio | F1: id_casello_fine | G1: tipo
A2: 1 | B2: A1 | C2: E35 | D2: Milano - Napoli (Aut. del sole) | E2: 1 | F2: 3 | G2: autostrada
A3: 2 | B3: A2 | C3: E45 | D3: Salerno - Reggio Calabria (Autostrada del Mediterraneo) | E3: 58 | F3: 8 | G3: autostrada
A4: 3 | B4: A3 | C4: E45 | D4: Napoli - Salerno | E4: 4 | F4: 58 | G4: autostrada
A5: 4 | B5: A4 | C5: E70 | D5: Torino - Trieste | E5: 5 | F5: 9 | G5: autostrada
A6: 5 | B6: A5 | C6: E70 | D6: Torino - Aosta - M.Bianco | E6: 6 | F6: 10 | G6: autostrada
A7: 6 | B7: A6 | C7: E717 | D7: Torino - Savona (La Verdemare) | E7: 7 | F7: 11 | G7: autostrada
A8: 7 | B8: A7 | C8: E62 | D8: Milano - Genova | E8: 2 | F8: 13 | G8: autostrada
A9: 8 | B9: A8 | C9: E62 | D9: Milano - Varese (Aut. Dei laghi) | E9: 14 | F9: 15 | G9: autostrada
A10: 9 | B10: A9 | C10: E35 | D10: Lainate - Chiasso | E10: 16 | F10: 17 | G10: autostrada
A11: 10 | B11: A10 | C11: E80 | D11: Genova - Ventimiglia (Aut. Dei Fiori) | E11: 13 | F11: 18 | G11: autostrada
A12: 11 | B12: A11 | C12: E76 | D12: Firenze - Pisa (Aut.Firenze Mare) | E12: 19 | F12: 20 | G12: autostrada
A13: 12 | B13: A12 | C13: E80 | D13: Genova - Rosignano Marittimo (Aut. Azzurra) | E13: 12 | F13: 26 | G13: autostrada
... A54: 53 | B54: A35 | C54: - | D54: Brebemi (Brescia - Milano) | E54: 102 | F54: 103 | G54: autostrada

Sheet caselli
A1: id | B1: nome | C1: lat | D1: lon
A2: 1 | B2: Milano S.Giuliano | C2: 45.428378 | D2: 9.247174
A3: 2 | B3: Milano Famagosta | C3: 45.435488 | D3: 9.170119
A4: 3 | B4: Napoli Nord | C4: 40.852174 | D4: 14.317121
A5: 4 | B5: Napoli Porto | C5: 40.85096 | D5: 14.278839
A6: 5 | B6: Torino Corso Giulio | C6: 45.119597 | D6: 7.711595
A7: 6 | B7: Torino Nord - Settimo T. | C7: 45.142835 | D7: 7.732227
A8: 7 | B8: Torino Sud - Moncalieri | C8: 44.967808 | D8: 7.703304
A9: 8 | B9: Reggio Calabria | C9: 38.133513 | D9: 15.65809
A10: 9 | B10: Trieste Sistiana | C10: 45.767391 | D10: 13.648412
A11: 10 | B11: Courmayeur-Monte Bianco | C11: 45.78287 | D11: 6.967087
A12: 11 | B12: Savona Vado | C12: 44.290503 | D12: 8.4402
A13: 12 | B13: Genova Est | C13: 44.445195 | D13: 8.904768
... A88: 88 | B88: Santhià Ovest | C88: 45.372423 | D88: 8.122836
A89: 89 | B89: Pero (A4/A8)
A90: 90 | B90: San Giuliano Milanese (A1)
A91: 91 | B91: Melegnano (A1)
A92: 92 | B92: Vimercate (A4)
A93: 93 | B93: Rho (A4)
A94: 94 | B94: Cinisello Balsamo (A4)
A95: 95 | B95: Stura (A4/A5)
A96: 96 | B96: Moncalieri (A6)
A97: 97 | B97: Agrate (A4)
A98: 98 | B98: GRA km 0
A99: 99 | B99: GRA km 68
A100: 100 | B100: Roma (GRA)
... A107: 107 | B107: Torino

Sheet correzioni_log
A1: id | B1: data | C1: tabella | D1: id_riga | E1: campo | F1: vecchio | G1: nuovo | H1: motivo
A2: 1 | B2: 2026-10-03 | C2: autostrade | D2: 2 | E2: riga | F2: - | G2: A2 Salerno - Reggio Calabria | H2: dal 2016 la ex A3 Salerno-Reggio Calabria si chiama A2
A3: 2 | B3: 2026-10-03 | C3: autostrade | D3: 3 | E3: nome | F3: Napoli - Reggio Calabria | G3: Napoli - Salerno | H3: A3 resta solo Napoli-Salerno
A4: 3 | B4: 2026-10-03 | C4: tratte | D4: 3 | E4: id_autostrada | F4: 3 | G4: 2 | H4: Salerno-Reggio Calabria passa ad A2
A5: 4 | B5: 2026-10-03 | C5: aree_servizio | D5: 57 | E5: id_autostrada | F5: 3 | G5: 2 | H5: area sulla Salerno-Reggio Calabria: A2 (indirizzi Ministero "A2 Autostrada del Mediterraneo")
A6: 5 | B6: 2026-10-03 | C6: aree_servizio | D6: 58 | E6: id_autostrada | F6: 3 | G6: 2 | H6: area sulla Salerno-Reggio Calabria: A2 (indirizzi Ministero "A2 Autostrada del Mediterraneo")
A7: 6 | B7: 2026-10-03 | C7: aree_servizio | D7: 59 | E7: id_autostrada | F7: 3 | G7: 2 | H7: area sulla Salerno-Reggio Calabria: A2 (indirizzi Ministero "A2 Autostrada del Mediterraneo")
A8: 7 | B8: 2026-10-03 | C8: aree_servizio | D8: 60 | E8: id_autostrada | F8: 3 | G8: 2 | H8: area sulla Salerno-Reggio Calabria: A2 (indirizzi Ministero "A2 Autostrada del Mediterraneo")
A9: 8 | B9: 2026-10-03 | C9: aree_servizio | D9: 61 | E9: id_autostrada | F9: 3 | G9: 2 | H9: area sulla Salerno-Reggio Calabria: A2 (indirizzi Ministero "A2 Autostrada del Mediterraneo")
A10: 9 | B10: 2026-10-03 | C10: aree_servizio | D10: 62 | E10: id_autostrada | F10: 3 | G10: 2 | H10: area sulla Salerno-Reggio Calabria: A2 (indirizzi Ministero "A2 Autostrada del Mediterraneo")
A11: 10 | B11: 2026-10-03 | C11: aree_servizio | D11: 63 | E11: id_autostrada | F11: 3 | G11: 2 | H11: area sulla Salerno-Reggio Calabria: A2 (indirizzi Ministero "A2 Autostrada del Mediterraneo")
A12: 11 | B12: 2026-10-03 | C12: aree_servizio | D12: 64 | E12: id_autostrada | F12: 3 | G12: 2 | H12: area sulla Salerno-Reggio Calabria: A2 (indirizzi Ministero "A2 Autostrada del Mediterraneo")
A13: 12 | B13: 2026-10-03 | C13: aree_servizio | D13: 65 | E13: id_autostrada | F13: 3 | G13: 2 | H13: area sulla Salerno-Reggio Calabria: A2 (indirizzi Ministero "A2 Autostrada del Mediterraneo")
... A263: 262 | B263: 2026-10-18 | C263: aree_servizio | D263: 9 | E263: attiva_2026 | F263: -1 | G263: -1 | H263: ricontrollata il 18/10/2026: resta esclusa. Area dismessa sulla vecchia carreggiata A1 ad Aglio (Wikipedia, voce Autostrada A1 var: 'dismessa'; notizia di chiusura su trasporti-italia.com); in direzione Firenze/Napoli la sostituisce Badia Nuova Ovest (aperta 1/04/2016). Nessun impianto del Ministero. Le schede online con Q8/Sarni al km 256,4 sono dati vecchi. Corretto il motivo dell'esclusione del 3/10.
A264: 263 | B264: 2026-10-18 | C264: aree_servizio | E264: km_cippo | G264: nuova colonna | H264: km ufficiale da mostrare (cippo, contato dall'inizio dell'autostrada). 'km' resta progressivo nel senso di marcia per il calcolo. 202 aree nella carreggiata verso l'inizio convertite con L - km (L = mediana di km Est + km Ovest delle coppie affacciate, per autostrada); le altre uguali a km. Precisione circa ±2 km dove le coppie non sono allineate.

Sheet da_verificare
A1: tabella | B1: id | C1: campo | D1: problema
A2: aree_marche_carburante | B2: 44 | C2: marca | D2: marca carburante mancante ("-")
A3: aree_marche_carburante | B3: 326 | C3: marca | D3: marca carburante mancante ("-")
A4: aree_marche_carburante | B4: 338 | C4: marca | D4: marca carburante mancante ("-")
A5: aree_marche_carburante | B5: 399 | C5: marca | D5: marca carburante mancante ("-")
A6: aree_marche_carburante | B6: 400 | C6: marca | D6: marca carburante mancante ("-")
A7: aree_marche_carburante | B7: 401 | C7: marca | D7: marca carburante mancante ("-")
A8: aree_marche_carburante | B8: 402 | C8: marca | D8: marca carburante mancante ("-")
A9: aree_marche_carburante | B9: 403 | C9: marca | D9: marca carburante mancante ("-")
A10: aree_marche_carburante | B10: 404 | C10: marca | D10: marca carburante mancante ("-")
A11: aree_marche_carburante | B11: 433 | C11: marca | D11: marca carburante mancante ("-")
A12: aree_marche_carburante | B12: 434 | C12: marca | D12: marca carburante mancante ("-")
A13: aree_marche_ristorante | B13: 44 | C13: marca | D13: nessuna marca ristorante ("-")
... A207: aree_servizio | B207: 480 | C207: stato | D207: Tangenziale di Napoli: nella schermata le tre aree sul lato verso Capodichino (Antica Campana Est, Agnano Est, Scudillo Est) hanno il semaforo rosso: forse chiusure temporanee per i lavori notturni; non segnate come chiuse

Sheet gestori_ricarica
A1: id | B1: nome
A2: 1 | B2: Free To X
A3: 2 | B3: Ionity
A4: 3 | B4: Enel X Way
A5: 4 | B5: Be Charge
A6: 5 | B6: Ewiva
A7: 6 | B7: Altro gestore
A8: 7 | B8: EG Italia
A9: 8 | B9: Enilive
A10: 9 | B10: IP
A11: 10 | B11: Agea Hotel
A12: 11 | B12: Autogrill
A13: 12 | B13: Tamoil
... A23: 22 | B23: Atlante

Sheet impianti_ministero
A1: id_area | B1: id_impianto | C1: bandiera_attuale | D1: criterio | E1: affidabilita | F1: distanza_coordinate_km | G1: _area
A2: 176 | B2: 3850 | C2: Agip Eni | D2: nome+posizione | E2: alta | F2: 0 | G2: =IF(A2="","",IFERROR(INDEX(aree_servizio!B:B,MATCH(A2,aree_servizio!A:A,0)),"?"))
A3: 82 | B3: 3987 | C3: Agip Eni | D3: nome (SETTIMO TORINESE SUD) + km + direzione Milano; coordinate del Ministero a 594 m dall'area | E3: alta | F3: 0.59 | G3: =IF(A3="","",IFERROR(INDEX(aree_servizio!B:B,MATCH(A3,aree_servizio!A:A,0)),"?"))
A4: 271 | B4: 37044 | C4: Agip Eni | D4: nome+posizione | E4: alta | F4: 0 | G4: =IF(A4="","",IFERROR(INDEX(aree_servizio!B:B,MATCH(A4,aree_servizio!A:A,0)),"?"))
A5: 57 | B5: 50581 | C5: Agip Eni | D5: nome+posizione | E5: alta | F5: 0 | G5: =IF(A5="","",IFERROR(INDEX(aree_servizio!B:B,MATCH(A5,aree_servizio!A:A,0)),"?"))
A6: 43 | B6: 3486 | C6: Api-Ip | D6: nome+posizione | E6: alta | F6: 0 | G6: =IF(A6="","",IFERROR(INDEX(aree_servizio!B:B,MATCH(A6,aree_servizio!A:A,0)),"?"))
A7: 14 | B7: 29384 | C7: Q8 | D7: nome+posizione | E7: alta | F7: 0.01 | G7: =IF(A7="","",IFERROR(INDEX(aree_servizio!B:B,MATCH(A7,aree_servizio!A:A,0)),"?"))
A8: 27 | B8: 62705 | C8: Sarni Oil | D8: nome+posizione | E8: alta | F8: 0.01 | G8: =IF(A8="","",IFERROR(INDEX(aree_servizio!B:B,MATCH(A8,aree_servizio!A:A,0)),"?"))
A9: 27 | B9: 41853 | C9: Sarni Oil | D9: nome+posizione | E9: alta | F9: 0.01 | G9: =IF(A9="","",IFERROR(INDEX(aree_servizio!B:B,MATCH(A9,aree_servizio!A:A,0)),"?"))
A10: 192 | B10: 3563 | C10: Esso | D10: nome+posizione | E10: alta | F10: 0.01 | G10: =IF(A10="","",IFERROR(INDEX(aree_servizio!B:B,MATCH(A10,aree_servizio!A:A,0)),"?"))
A11: 373 | B11: 40495 | C11: Tamoil | D11: nome+posizione | E11: alta | F11: 0.01 | G11: =IF(A11="","",IFERROR(INDEX(aree_servizio!B:B,MATCH(A11,aree_servizio!A:A,0)),"?"))
A12: 221 | B12: 53675 | C12: Api-Ip | D12: nome+posizione | E12: alta | F12: 0.01 | G12: =IF(A12="","",IFERROR(INDEX(aree_servizio!B:B,MATCH(A12,aree_servizio!A:A,0)),"?"))
A13: 235 | B13: 62727 | C13: Esso | D13: nome+posizione | E13: alta | F13: 0.01 | G13: =IF(A13="","",IFERROR(INDEX(aree_servizio!B:B,MATCH(A13,aree_servizio!A:A,0)),"?"))
... A453: 60 | B453: 59039 | C453: Q8 | D453: nome + km coerente (coordinate del Ministero imprecise) | E453: alta | F453: 6.24 | G453: =IF(A453="","",IFERROR(INDEX(aree_servizio!B:B,MATCH(A453,aree_servizio!A:A,0)),"?"))
A454: 3 | B454: 3473 | C454: Agip Eni | D454: solo nome (area senza coordinate) | E454: alta | G454: =IF(A454="","",IFERROR(INDEX(aree_servizio!B:B,MATCH(A454,aree_servizio!A:A,0)),"?"))
A455: 44 | B455: 62720 | C455: Sarni Oil | D455: impianto classificato autostradale dal Ministero ma probabilmente su strada locale | E455: media | F455: 0.04 | G455: =IF(A455="","",IFERROR(INDEX(aree_servizio!B:B,MATCH(A455,aree_servizio!A:A,0)),"?"))
A456: 44 | B456: 36724 | C456: Sarni Oil | D456: impianto classificato autostradale dal Ministero ma probabilmente su strada locale | E456: media | F456: 0.04 | G456: =IF(A456="","",IFERROR(INDEX(aree_servizio!B:B,MATCH(A456,aree_servizio!A:A,0)),"?"))
A457: 154 | B457: 44860 | C457: Api-Ip | D457: stesso luogo (coordinate coincidenti), nome diverso | E457: alta | F457: 0.12 | G457: =IF(A457="","",IFERROR(INDEX(aree_servizio!B:B,MATCH(A457,aree_servizio!A:A,0)),"?"))
A458: 127 | B458: 52063 | C458: Api-Ip | D458: stesso luogo (coordinate coincidenti), nome diverso | E458: alta | F458: 0 | G458: =IF(A458="","",IFERROR(INDEX(aree_servizio!B:B,MATCH(A458,aree_servizio!A:A,0)),"?"))
A459: 130 | B459: 47886 | C459: Agip Eni | D459: stesso luogo (coordinate coincidenti), nome diverso | E459: alta | F459: 0.03 | G459: =IF(A459="","",IFERROR(INDEX(aree_servizio!B:B,MATCH(A459,aree_servizio!A:A,0)),"?"))
A460: 129 | B460: 60161 | C460: Pompe Bianche | D460: stesso luogo (coordinate coincidenti), nome diverso | E460: alta | F460: 0.01 | G460: =IF(A460="","",IFERROR(INDEX(aree_servizio!B:B,MATCH(A460,aree_servizio!A:A,0)),"?"))
A461: 345 | B461: 41081 | C461: Tamoil | D461: stesso luogo (coordinate coincidenti), nome diverso | E461: alta | F461: 0.01 | G461: =IF(A461="","",IFERROR(INDEX(aree_servizio!B:B,MATCH(A461,aree_servizio!A:A,0)),"?"))
A462: 326 | B462: 51972 | C462: Agip Eni | D462: stesso luogo (coordinate coincidenti), nome diverso | E462: alta | F462: 0.48 | G462: =IF(A462="","",IFERROR(INDEX(aree_servizio!B:B,MATCH(A462,aree_servizio!A:A,0)),"?"))
A463: 426 | B463: 62774 | C463: Agip Eni | D463: stesso luogo (coordinate coincidenti), nome diverso | E463: alta | F463: 0.01 | G463: =IF(A463="","",IFERROR(INDEX(aree_servizio!B:B,MATCH(A463,aree_servizio!A:A,0)),"?"))
A464: 426 | B464: 42903 | C464: Agip Eni | D464: stesso luogo (coordinate coincidenti), nome diverso | E464: alta | F464: 0.01 | G464: =IF(A464="","",IFERROR(INDEX(aree_servizio!B:B,MATCH(A464,aree_servizio!A:A,0)),"?"))
A465: 430 | B465: 22226 | C465: Agip Eni | D465: stesso luogo (coordinate coincidenti), nome diverso | E465: alta | F465: 0.03 | G465: =IF(A465="","",IFERROR(INDEX(aree_servizio!B:B,MATCH(A465,aree_servizio!A:A,0)),"?"))
A466: 333 | B466: 62753 | C466: Sarni Oil | D466: nome + km + autostrada | E466: alta | F466: 0 | G466: =IF(A466="","",IFERROR(INDEX(aree_servizio!B:B,MATCH(A466,aree_servizio!A:A,0)),"?"))
... A528: 362 | B528: 48564 | C528: Q8 | D528: nome (LA RUSTICA NORD) + posizione (10 m) + A24 km 1 | E528: alta | F528: 0.01 | G528: =IF(A528="","",IFERROR(INDEX(aree_servizio!B:B,MATCH(A528,aree_servizio!A:A,0)),"?"))

Sheet info_aggiornamento
A1: chiave | B1: valore
A2: fonte | B2: MIMIT Osservaprezzi Carburanti, open data IODL 2.0
A3: data_estrazione | B3: 2026-10-01
A4: nota | B4: prezzi alle ore 8 del giorno precedente; coordinate del Ministero inserite dai gestori e non sempre verificate
A5: nota_app | B5: le aree con attiva_2026=0 sono nascoste nell'app finché non verificate
A6: correzioni | B6: 3 ottobre 2026: vedi tabella correzioni_log
A7: attiva_2026 | B7: 1 = visibile; 0 = nascosta (non trovata nel Ministero); -1 = esclusa (non è su autostrada)
A8: tipo_autostrade | B8: autostrade.tipo = tangenziale usa una tolleranza di posizione ridotta nel motore
A9: stato | B9: aree_servizio.stato: aperta oppure chiusa (temporaneamente); l'app mostra un avviso
A10: data_cambi | B10: 2026-10-16

Sheet marche_carburante
A1: id | B1: nome
A2: 1 | B2: Agip
A3: 2 | B3: Api
A4: 3 | B4: Eni
A5: 4 | B5: Erg
A6: 5 | B6: Esso
A7: 6 | B7: IP
A8: 7 | B8: Ies
A9: 8 | B9: Omv
A10: 9 | B10: Q8
A11: 10 | B11: Repsol
A12: 11 | B12: Shell
A13: 12 | B13: Tamoil
... A23: 22 | B23: RPetroli

Sheet marche_ristorante
A1: id | B1: nome
A2: 1 | B2: Alemagna
A3: 2 | B3: Autogrill
A4: 3 | B4: Bauli
A5: 4 | B5: Burger King
A6: 5 | B6: Camst
A7: 6 | B7: Chef Express
A8: 7 | B8: Ciao
A9: 8 | B9: Fini
A10: 9 | B10: Mc Donald's
A11: 10 | B11: Miramare
A12: 11 | B12: My Chef
A13: 12 | B13: Pramagrill
... A19: 18 | B19: EuroChef

Sheet prezzi
A1: id_area | B1: id_impianto | C1: carburante | D1: modalita | E1: prezzo | F1: data_comunicazione | G1: data_estrazione | H1: _area
